Workbook
Name Etapas: Listas!$A$3:$A$7
Name FasesExt: Listas!$B$3:$B$8
Name Roles: Listas!$C$3:$C$18
Name CodigosRol: Listas!$D$3:$D$18

Sheet Instrucciones
A1: Matriz de roles RACI
A2: Kit de implementación AWP · Proyecto Tipo (PT) – Complejo de instalaciones en tres fases
A4: Propósito | B4: Definir quién ejecuta (R), quién aprueba (A), a quién se consulta (C) y a quién se informa (I) en cada actividad AWP, por etapa del ciclo de vida, para que no queden actividades sin dueño ni con dueños duplicados.
A5: Cuándo se usa | B5: En la planificación temprana global (antes del hito H0) y en el arranque de cada fase del proyecto. Se revisa cuando cambia la organización o se incorpora un subcontratista.
A6: Quién la llena | B6: El AWP Champion la prepara con los líderes funcionales; la aprueba el Gerente de Proyecto y se comunica a todo el equipo.
A7: Cómo llenarla | B7: 1. Revise la lista de actividades y agregue las propias del proyecto al final (la numeración es libre). 2. Para cada actividad, elija R, A, C o I en la columna de cada rol (lista desplegable). Deje vacío si el rol no participa. 3. Asigne exactamente una «A» por actividad. La columna «Verificación» avisa en rojo si hay cero o más de una. 4. Indique en «Fase del proyecto» si la actividad aplica a todas las fases o a una en particular. 5. Revise la hoja «Resumen por rol» para detectar roles sobrecargados o sin participación. 6. La hoja «Roles» describe cada código de rol; los mismos códigos se usan en todo el kit.
A8: Colores | B8: Amarillo: fila de ejemplo (bórrela o reemplácela). Encabezado azul oscuro: dato que se ingresa. Encabezado azul medio y celda gris: columna calculada con fórmula (no la sobrescriba). Rojo: vencido o fuera de meta. Ámbar: por vencer o cerca del límite. Verde: cumplido.
A9: Impresión | B9: Cada hoja está configurada en A4, ajustada al ancho de la página, con el encabezado repetido en cada página. El área de impresión de las hojas de datos cubre las primeras 50 filas: si usa más, amplíela en Diseño de página > Área de impresión.
A10: Nota | B10: A diferencia de otras plantillas, esta matriz no tiene filas de ejemplo: es la propuesta del proyecto tipo y se ajusta directamente.
A12: Columnas de la hoja «Matriz RACI»
A13: Columna | B13: Significado | C13: Tipo de dato
A14: N.° | B14: Número correlativo de la actividad. | C14: Manual
A15: Etapa del ciclo de vida | B15: Etapa del ciclo de vida en que se realiza la actividad. | C15: Lista
A16: Actividad AWP | B16: Actividad del proceso AWP. | C16: Manual
A17: Fase del proyecto | B17: Fases en que aplica la actividad. | C17: Lista
A18: N.° de A | B18: Calculado: cantidad de «A» en la fila. Debe ser exactamente 1. | C18: Calculado
A19: N.° de R | B19: Calculado: cantidad de «R» en la fila. | C19: Calculado
A20: Verificación | B20: Calculado: «OK» si hay una sola A; «Revisar» si no. | C20: Calculado
A21: Columnas de roles (CLI … SUB) | B21: Una columna por rol con R, A, C o I. Ver la hoja «Roles». | C21: Lista

Sheet Matriz RACI
A1: Matriz de roles y responsabilidades AWP (RACI)
A2: Proyecto Tipo (PT) – Complejo de instalaciones en tres fases. Matriz propuesta para el proyecto tipo: ajústela en el taller de arranque de cada fase. R = responsable de ejecutar; A = aprueba y rinde cuentas (una sola por actividad); C = consultado; I = informado.
A5: N.° | B5: Etapa del ciclo de vida | C5: Actividad AWP | D5: Fase del proyecto | E5: CLI | F5: GP | G5: CHA | H5: LWF | I5: WFP | J5: ING | K5: PRO | L5: MAT | M5: CON | N5: SUP | O5: CTR | P5: IM | Q5: HSE | R5: CAL | S5: COM | T5: SUB | U5: N.° de A | V5: N.° de R | W5: Verificación
A6: 1 | B6: Planificación temprana (FEL) | C6: Aprobar la estrategia y el plan de implementación AWP | D6: Todas las fases | E6: A | F6: R | G6: R | J6: C | K6: C | M6: C | O6: C | S6: I | U6: =IF(C6="","",COUNTIF(E6:T6,"A")) | V6: =IF(C6="","",COUNTIF(E6:T6,"R")) | W6: =IF(C6="","",IF(U6<>1,"Revisar: debe haber una sola A",IF(V6=0,"OK (A ejecuta)","OK")))
A7: 2 | B7: Planificación temprana (FEL) | C7: Designar al AWP Champion y al equipo AWP | D7: Todas las fases | E7: C | F7: A | G7: I | M7: C | U7: =IF(C7="","",COUNTIF(E7:T7,"A")) | V7: =IF(C7="","",COUNTIF(E7:T7,"R")) | W7: =IF(C7="","",IF(U7<>1,"Revisar: debe haber una sola A",IF(V7=0,"OK (A ejecuta)","OK")))
A8: 3 | B8: Planificación temprana (FEL) | C8: Evaluar la escala de AWP y definir el nivel de madurez por fase | D8: Todas las fases | E8: C | F8: A | G8: R | M8: C | O8: C | U8: =IF(C8="","",COUNTIF(E8:T8,"A")) | V8: =IF(C8="","",COUNTIF(E8:T8,"R")) | W8: =IF(C8="","",IF(U8<>1,"Revisar: debe haber una sola A",IF(V8=0,"OK (A ejecuta)","OK")))
A9: 4 | B9: Planificación temprana (FEL) | C9: Definir las CWA de la fase | D9: Todas las fases | E9: C | G9: A | J9: C | M9: R | O9: C | P9: I | S9: C | U9: =IF(C9="","",COUNTIF(E9:T9,"A")) | V9: =IF(C9="","",COUNTIF(E9:T9,"R")) | W9: =IF(C9="","",IF(U9<>1,"Revisar: debe haber una sola A",IF(V9=0,"OK (A ejecuta)","OK")))
A10: 5 | B10: Planificación temprana (FEL) | C10: Desarrollar el Path of Construction en talleres IPP | D10: Todas las fases | E10: C | G10: R | H10: C | J10: C | K10: C | M10: A | O10: C | Q10: C | S10: C | U10: =IF(C10="","",COUNTIF(E10:T10,"A")) | V10: =IF(C10="","",COUNTIF(E10:T10,"R")) | W10: =IF(C10="","",IF(U10<>1,"Revisar: debe haber una sola A",IF(V10=0,"OK (A ejecuta)","OK")))
A11: 6 | B11: Planificación temprana (FEL) | C11: Elaborar el plan de liberación CWP/EWP/PWP | D11: Todas las fases | G11: A | H11: C | J11: R | K11: R | M11: R | O11: R | U11: =IF(C11="","",COUNTIF(E11:T11,"A")) | V11: =IF(C11="","",COUNTIF(E11:T11,"R")) | W11: =IF(C11="","",IF(U11<>1,"Revisar: debe haber una sola A",IF(V11=0,"OK (A ejecuta)","OK")))
A12: 7 | B12: Planificación temprana (FEL) | C12: Definir la WBS y la codificación de paquetes | D12: Todas las fases | G12: A | J12: C | K12: C | M12: C | O12: R | P12: R | U12: =IF(C12="","",COUNTIF(E12:T12,"A")) | V12: =IF(C12="","",COUNTIF(E12:T12,"R")) | W12: =IF(C12="","",IF(U12<>1,"Revisar: debe haber una sola A",IF(V12=0,"OK (A ejecuta)","OK")))
A13: 8 | B13: Planificación temprana (FEL) | C13: Incluir los requisitos AWP en contratos y subcontratos | D13: Todas las fases | E13: C | F13: A | G13: C | K13: R | T13: I | U13: =IF(C13="","",COUNTIF(E13:T13,"A")) | V13: =IF(C13="","",COUNTIF(E13:T13,"R")) | W13: =IF(C13="","",IF(U13<>1,"Revisar: debe haber una sola A",IF(V13=0,"OK (A ejecuta)","OK")))
A14: 9 | B14: Planificación temprana (FEL) | C14: Definir los requisitos de gestión de la información y del modelo 3D | D14: Todas las fases | G14: A | J14: C | K14: C | O14: C | P14: R | U14: =IF(C14="","",COUNTIF(E14:T14,"A")) | V14: =IF(C14="","",COUNTIF(E14:T14,"R")) | W14: =IF(C14="","",IF(U14<>1,"Revisar: debe haber una sola A",IF(V14=0,"OK (A ejecuta)","OK")))
A15: 10 | B15: Planificación temprana (FEL) | C15: Implementar el software de WFP integrado con modelo, cronograma y materiales | D15: Fase 2 | G15: A | H15: C | J15: C | K15: C | O15: C | P15: R | U15: =IF(C15="","",COUNTIF(E15:T15,"A")) | V15: =IF(C15="","",COUNTIF(E15:T15,"R")) | W15: =IF(C15="","",IF(U15<>1,"Revisar: debe haber una sola A",IF(V15=0,"OK (A ejecuta)","OK")))
A16: 11 | B16: Ingeniería | C16: Planificar la ingeniería por EWP según el PoC | D16: Todas las fases | G16: C | J16: A | M16: C | O16: R | U16: =IF(C16="","",COUNTIF(E16:T16,"A")) | V16: =IF(C16="","",COUNTIF(E16:T16,"R")) | W16: =IF(C16="","",IF(U16<>1,"Revisar: debe haber una sola A",IF(V16=0,"OK (A ejecuta)","OK")))
A17: 12 | B17: Ingeniería | C17: Emitir EWP completos (IFC y MTO) en la secuencia del PoC | D17: Todas las fases | G17: I | H17: I | J17: A | K17: I | M17: I | U17: =IF(C17="","",COUNTIF(E17:T17,"A")) | V17: =IF(C17="","",COUNTIF(E17:T17,"R")) | W17: =IF(C17="","",IF(U17<>1,"Revisar: debe haber una sola A",IF(V17=0,"OK (A ejecuta)","OK")))
A18: 13 | B18: Ingeniería | C18: Mantener el modelo 3D con atributos AWP | D18: Todas las fases | H18: C | I18: I | J18: R | P18: A | U18: =IF(C18="","",COUNTIF(E18:T18,"A")) | V18: =IF(C18="","",COUNTIF(E18:T18,"R")) | W18: =IF(C18="","",IF(U18<>1,"Revisar: debe haber una sola A",IF(V18=0,"OK (A ejecuta)","OK")))
A19: 14 | B19: Ingeniería | C19: Revisar la constructabilidad antes de la emisión IFC | D19: Todas las fases | J19: A | M19: R | N19: C | Q19: C | R19: C | U19: =IF(C19="","",COUNTIF(E19:T19,"A")) | V19: =IF(C19="","",COUNTIF(E19:T19,"R")) | W19: =IF(C19="","",IF(U19<>1,"Revisar: debe haber una sola A",IF(V19=0,"OK (A ejecuta)","OK")))
A20: 15 | B20: Ingeniería | C20: Responder las RFI | D20: Todas las fases | H20: I | I20: C | J20: A | M20: I | U20: =IF(C20="","",COUNTIF(E20:T20,"A")) | V20: =IF(C20="","",COUNTIF(E20:T20,"R")) | W20: =IF(C20="","",IF(U20<>1,"Revisar: debe haber una sola A",IF(V20=0,"OK (A ejecuta)","OK")))
A21: 16 | B21: Procura | C21: Estructurar las compras en PWP por CWP | D21: Todas las fases | G21: C | J21: C | K21: A | L21: C | M21: C | U21: =IF(C21="","",COUNTIF(E21:T21,"A")) | V21: =IF(C21="","",COUNTIF(E21:T21,"R")) | W21: =IF(C21="","",IF(U21<>1,"Revisar: debe haber una sola A",IF(V21=0,"OK (A ejecuta)","OK")))
A22: 17 | B22: Procura | C22: Alinear las fechas RAS con el PoC | D22: Todas las fases | J22: C | K22: A | M22: C | O22: R | U22: =IF(C22="","",COUNTIF(E22:T22,"A")) | V22: =IF(C22="","",COUNTIF(E22:T22,"R")) | W22: =IF(C22="","",IF(U22<>1,"Revisar: debe haber una sola A",IF(V22=0,"OK (A ejecuta)","OK")))
A23: 18 | B23: Procura | C23: Informar el estado de materiales por CWP e IWP | D23: Todas las fases | H23: I | I23: I | K23: A | L23: R | U23: =IF(C23="","",COUNTIF(E23:T23,"A")) | V23: =IF(C23="","",COUNTIF(E23:T23,"R")) | W23: =IF(C23="","",IF(U23<>1,"Revisar: debe haber una sola A",IF(V23=0,"OK (A ejecuta)","OK")))
A24: 19 | B24: Procura | C24: Reservar y despachar materiales por IWP | D24: Todas las fases | I24: C | K24: C | L24: A | N24: I | U24: =IF(C24="","",COUNTIF(E24:T24,"A")) | V24: =IF(C24="","",COUNTIF(E24:T24,"R")) | W24: =IF(C24="","",IF(U24<>1,"Revisar: debe haber una sola A",IF(V24=0,"OK (A ejecuta)","OK")))
A25: 20 | B25: Procura | C25: Gestionar la documentación del proveedor | D25: Todas las fases | J25: C | K25: A | R25: C | S25: C | U25: =IF(C25="","",COUNTIF(E25:T25,"A")) | V25: =IF(C25="","",COUNTIF(E25:T25,"R")) | W25: =IF(C25="","",IF(U25<>1,"Revisar: debe haber una sola A",IF(V25=0,"OK (A ejecuta)","OK")))
A26: 21 | B26: Construcción | C26: Emitir los CWP | D26: Todas las fases | H26: R | J26: C | K26: C | M26: A | O26: C | Q26: C | R26: C | U26: =IF(C26="","",COUNTIF(E26:T26,"A")) | V26: =IF(C26="","",COUNTIF(E26:T26,"R")) | W26: =IF(C26="","",IF(U26<>1,"Revisar: debe haber una sola A",IF(V26=0,"OK (A ejecuta)","OK")))
A27: 22 | B27: Construcción | C27: Dividir los CWP en IWP | D27: Todas las fases | H27: A | I27: R | N27: C | O27: I | U27: =IF(C27="","",COUNTIF(E27:T27,"A")) | V27: =IF(C27="","",COUNTIF(E27:T27,"R")) | W27: =IF(C27="","",IF(U27<>1,"Revisar: debe haber una sola A",IF(V27=0,"OK (A ejecuta)","OK")))
A28: 23 | B28: Construcción | C28: Identificar y registrar restricciones | D28: Todas las fases | H28: A | I28: R | N28: C | T28: R | U28: =IF(C28="","",COUNTIF(E28:T28,"A")) | V28: =IF(C28="","",COUNTIF(E28:T28,"R")) | W28: =IF(C28="","",IF(U28<>1,"Revisar: debe haber una sola A",IF(V28=0,"OK (A ejecuta)","OK")))
A29: 24 | B29: Construcción | C29: Levantar las restricciones asignadas | D29: Todas las fases | H29: A | J29: R | K29: R | L29: R | N29: R | Q29: R | U29: =IF(C29="","",COUNTIF(E29:T29,"A")) | V29: =IF(C29="","",COUNTIF(E29:T29,"R")) | W29: =IF(C29="","",IF(U29<>1,"Revisar: debe haber una sola A",IF(V29=0,"OK (A ejecuta)","OK")))
A30: 25 | B30: Construcción | C30: Dirigir la reunión semanal de restricciones | D30: Todas las fases | H30: A | I30: C | J30: C | K30: C | M30: C | N30: C | U30: =IF(C30="","",COUNTIF(E30:T30,"A")) | V30: =IF(C30="","",COUNTIF(E30:T30,"R")) | W30: =IF(C30="","",IF(U30<>1,"Revisar: debe haber una sola A",IF(V30=0,"OK (A ejecuta)","OK")))
A31: 26 | B31: Construcción | C31: Liberar IWP con el checklist de liberación | D31: Todas las fases | H31: A | I31: R | L31: C | N31: C | Q31: C | R31: C | U31: =IF(C31="","",COUNTIF(E31:T31,"A")) | V31: =IF(C31="","",COUNTIF(E31:T31,"R")) | W31: =IF(C31="","",IF(U31<>1,"Revisar: debe haber una sola A",IF(V31=0,"OK (A ejecuta)","OK")))
A32: 27 | B32: Construcción | C32: Seleccionar IWP del backlog (lookahead de 3 semanas) | D32: Todas las fases | H32: C | M32: A | N32: R | T32: C | U32: =IF(C32="","",COUNTIF(E32:T32,"A")) | V32: =IF(C32="","",COUNTIF(E32:T32,"R")) | W32: =IF(C32="","",IF(U32<>1,"Revisar: debe haber una sola A",IF(V32=0,"OK (A ejecuta)","OK")))
A33: 28 | B33: Construcción | C33: Ejecutar el IWP en campo | D33: Todas las fases | I33: I | N33: A | Q33: C | R33: C | T33: R | U33: =IF(C33="","",COUNTIF(E33:T33,"A")) | V33: =IF(C33="","",COUNTIF(E33:T33,"R")) | W33: =IF(C33="","",IF(U33<>1,"Revisar: debe haber una sola A",IF(V33=0,"OK (A ejecuta)","OK")))
A34: 29 | B34: Construcción | C34: Cerrar el IWP (avance, HH, calidad) | D34: Todas las fases | H34: A | I34: R | N34: R | O34: I | R34: R | U34: =IF(C34="","",COUNTIF(E34:T34,"A")) | V34: =IF(C34="","",COUNTIF(E34:T34,"R")) | W34: =IF(C34="","",IF(U34<>1,"Revisar: debe haber una sola A",IF(V34=0,"OK (A ejecuta)","OK")))
A35: 30 | B35: Construcción | C35: Calcular y reportar los KPI | D35: Todas las fases | E35: I | F35: I | G35: A | H35: R | O35: R | U35: =IF(C35="","",COUNTIF(E35:T35,"A")) | V35: =IF(C35="","",COUNTIF(E35:T35,"R")) | W35: =IF(C35="","",IF(U35<>1,"Revisar: debe haber una sola A",IF(V35=0,"OK (A ejecuta)","OK")))
A36: 31 | B36: Construcción | C36: Gestionar las interfaces entre fases superpuestas | D36: Fases 2 y 3 | G36: A | J36: C | M36: R | O36: C | S36: C | U36: =IF(C36="","",COUNTIF(E36:T36,"A")) | V36: =IF(C36="","",COUNTIF(E36:T36,"R")) | W36: =IF(C36="","",IF(U36<>1,"Revisar: debe haber una sola A",IF(V36=0,"OK (A ejecuta)","OK")))
A37: 32 | B37: Construcción | C37: Auditar el proceso AWP | D37: Todas las fases | E37: I | F37: I | G37: A | H37: C | M37: C | U37: =IF(C37="","",COUNTIF(E37:T37,"A")) | V37: =IF(C37="","",COUNTIF(E37:T37,"R")) | W37: =IF(C37="","",IF(U37<>1,"Revisar: debe haber una sola A",IF(V37=0,"OK (A ejecuta)","OK")))
A38: 33 | B38: Comisionamiento | C38: Definir los sistemas y la secuencia de puesta en marcha | D38: Todas las fases | E38: C | G38: C | J38: R | M38: C | S38: A | U38: =IF(C38="","",COUNTIF(E38:T38,"A")) | V38: =IF(C38="","",COUNTIF(E38:T38,"R")) | W38: =IF(C38="","",IF(U38<>1,"Revisar: debe haber una sola A",IF(V38=0,"OK (A ejecuta)","OK")))
A39: 34 | B39: Comisionamiento | C39: Relacionar los IWP con los sistemas | D39: Todas las fases | H39: R | I39: C | P39: R | S39: A | U39: =IF(C39="","",COUNTIF(E39:T39,"A")) | V39: =IF(C39="","",COUNTIF(E39:T39,"R")) | W39: =IF(C39="","",IF(U39<>1,"Revisar: debe haber una sola A",IF(V39=0,"OK (A ejecuta)","OK")))
A40: 35 | B40: Comisionamiento | C40: Preparar los SWP y TOP | D40: Todas las fases | E40: I | M40: C | N40: C | R40: R | S40: A | U40: =IF(C40="","",COUNTIF(E40:T40,"A")) | V40: =IF(C40="","",COUNTIF(E40:T40,"R")) | W40: =IF(C40="","",IF(U40<>1,"Revisar: debe haber una sola A",IF(V40=0,"OK (A ejecuta)","OK")))
A41: 36 | B41: Comisionamiento | C41: Capturar y transferir lecciones aprendidas | D41: Todas las fases | E41: I | F41: C | G41: A | H41: R | J41: C | K41: C | M41: C | S41: C | U41: =IF(C41="","",COUNTIF(E41:T41,"A")) | V41: =IF(C41="","",COUNTIF(E41:T41,"R")) | W41: =IF(C41="","",IF(U41<>1,"Revisar: debe haber una sola A",IF(V41=0,"OK (A ejecuta)","OK")))
A42: 37 | B42: Comisionamiento | C42: Elaborar el informe de cierre AWP de la fase | D42: Todas las fases | E42: I | F42: C | G42: A | H42: C | O42: C | U42: =IF(C42="","",COUNTIF(E42:T42,"A")) | V42: =IF(C42="","",COUNTIF(E42:T42,"R")) | W42: =IF(C42="","",IF(U42<>1,"Revisar: debe haber una sola A",IF(V42=0,"OK (A ejecuta)","OK")))
...

Sheet Roles
A1: Roles AWP del proyecto tipo
A2: Códigos usados en todas las plantillas del kit.
A4: Código | B4: Rol | C4: Responsabilidades AWP principales
A5: CLI | B5: Gerente del proyecto del cliente | C5: Patrocina AWP; aprueba el plan, el PoC y los hitos; exige requisitos AWP en contratos.
A6: GP | B6: Gerente de Proyecto | C6: Responsable final de la implementación; asigna recursos; resuelve restricciones escaladas.
A7: CHA | B7: AWP Champion | C7: Lidera la implementación; procedimientos, plantillas, formación, talleres de PoC, auditorías, KPI y lecciones.
A8: LWF | B8: Líder de WFP | C8: Coordina a los planificadores; dirige la reunión de restricciones; controla backlog y liberación de IWP.
A9: WFP | B9: Planificador de frente de trabajo | C9: Divide CWP en IWP; identifica restricciones; arma, libera y cierra IWP (1 por cada 50 trabajadores).
A10: ING | B10: Líder de Ingeniería | C10: Emite EWP en secuencia del PoC; mantiene el modelo 3D; responde RFI.
A11: PRO | B11: Líder de Procura | C11: Estructura PWP; alinea fechas RAS; informa estado de materiales; documentación del proveedor.
A12: MAT | B12: Gestor de materiales | C12: Recibe, reserva y despacha materiales por IWP.
A13: CON | B13: Gerente de Construcción | C13: Lidera el PoC; aprueba CWP; decide la secuencia de ejecución; prioriza restricciones críticas.
A14: SUP | B14: Superintendente / capataz general | C14: Selecciona IWP del backlog; ejecuta los IWP con sus capataces; informa avance.
A15: CTR | B15: Controles del proyecto | C15: Integra CWP (nivel 3) e IWP (nivel 5) en el cronograma; mide avance y productividad; calcula KPI.
... A20: SUB | B20: Subcontratista de especialidad | C20: Aplica AWP en su alcance; aporta planificadores; cumple el lookahead.

Sheet Resumen por rol
A1: Participación de cada rol
A2: Cantidad de actividades en que cada rol es R, A, C o I (calculado).
A4: Código | B4: Rol | C4: R | D4: A | E4: C | F4: I
A5: CLI | B5: Gerente del proyecto del cliente | C5: =COUNTIF('Matriz RACI'!$E$6:$E$65,"R") | D5: =COUNTIF('Matriz RACI'!$E$6:$E$65,"A") | E5: =COUNTIF('Matriz RACI'!$E$6:$E$65,"C") | F5: =COUNTIF('Matriz RACI'!$E$6:$E$65,"I")
A6: GP | B6: Gerente de Proyecto | C6: =COUNTIF('Matriz RACI'!$F$6:$F$65,"R") | D6: =COUNTIF('Matriz RACI'!$F$6:$F$65,"A") | E6: =COUNTIF('Matriz RACI'!$F$6:$F$65,"C") | F6: =COUNTIF('Matriz RACI'!$F$6:$F$65,"I")
A7: CHA | B7: AWP Champion | C7: =COUNTIF('Matriz RACI'!$G$6:$G$65,"R") | D7: =COUNTIF('Matriz RACI'!$G$6:$G$65,"A") | E7: =COUNTIF('Matriz RACI'!$G$6:$G$65,"C") | F7: =COUNTIF('Matriz RACI'!$G$6:$G$65,"I")
A8: LWF | B8: Líder de WFP | C8: =COUNTIF('Matriz RACI'!$H$6:$H$65,"R") | D8: =COUNTIF('Matriz RACI'!$H$6:$H$65,"A") | E8: =COUNTIF('Matriz RACI'!$H$6:$H$65,"C") | F8: =COUNTIF('Matriz RACI'!$H$6:$H$65,"I")
A9: WFP | B9: Planificador de frente de trabajo | C9: =COUNTIF('Matriz RACI'!$I$6:$I$65,"R") | D9: =COUNTIF('Matriz RACI'!$I$6:$I$65,"A") | E9: =COUNTIF('Matriz RACI'!$I$6:$I$65,"C") | F9: =COUNTIF('Matriz RACI'!$I$6:$I$65,"I")
A10: ING | B10: Líder de Ingeniería | C10: =COUNTIF('Matriz RACI'!$J$6:$J$65,"R") | D10: =COUNTIF('Matriz RACI'!$J$6:$J$65,"A") | E10: =COUNTIF('Matriz RACI'!$J$6:$J$65,"C") | F10: =COUNTIF('Matriz RACI'!$J$6:$J$65,"I")
A11: PRO | B11: Líder de Procura | C11: =COUNTIF('Matriz RACI'!$K$6:$K$65,"R") | D11: =COUNTIF('Matriz RACI'!$K$6:$K$65,"A") | E11: =COUNTIF('Matriz RACI'!$K$6:$K$65,"C") | F11: =COUNTIF('Matriz RACI'!$K$6:$K$65,"I")
A12: MAT | B12: Gestor de materiales | C12: =COUNTIF('Matriz RACI'!$L$6:$L$65,"R") | D12: =COUNTIF('Matriz RACI'!$L$6:$L$65,"A") | E12: =COUNTIF('Matriz RACI'!$L$6:$L$65,"C") | F12: =COUNTIF('Matriz RACI'!$L$6:$L$65,"I")
A13: CON | B13: Gerente de Construcción | C13: =COUNTIF('Matriz RACI'!$M$6:$M$65,"R") | D13: =COUNTIF('Matriz RACI'!$M$6:$M$65,"A") | E13: =COUNTIF('Matriz RACI'!$M$6:$M$65,"C") | F13: =COUNTIF('Matriz RACI'!$M$6:$M$65,"I")
A14: SUP | B14: Superintendente / capataz general | C14: =COUNTIF('Matriz RACI'!$N$6:$N$65,"R") | D14: =COUNTIF('Matriz RACI'!$N$6:$N$65,"A") | E14: =COUNTIF('Matriz RACI'!$N$6:$N$65,"C") | F14: =COUNTIF('Matriz RACI'!$N$6:$N$65,"I")
A15: CTR | B15: Controles del proyecto | C15: =COUNTIF('Matriz RACI'!$O$6:$O$65,"R") | D15: =COUNTIF('Matriz RACI'!$O$6:$O$65,"A") | E15: =COUNTIF('Matriz RACI'!$O$6:$O$65,"C") | F15: =COUNTIF('Matriz RACI'!$O$6:$O$65,"I")
A16: IM | B16: Coordinador de gestión de información | C16: =COUNTIF('Matriz RACI'!$P$6:$P$65,"R") | D16: =COUNTIF('Matriz RACI'!$P$6:$P$65,"A") | E16: =COUNTIF('Matriz RACI'!$P$6:$P$65,"C") | F16: =COUNTIF('Matriz RACI'!$P$6:$P$65,"I")
A17: HSE | B17: Líder de HSE | C17: =COUNTIF('Matriz RACI'!$Q$6:$Q$65,"R") | D17: =COUNTIF('Matriz RACI'!$Q$6:$Q$65,"A") | E17: =COUNTIF('Matriz RACI'!$Q$6:$Q$65,"C") | F17: =COUNTIF('Matriz RACI'!$Q$6:$Q$65,"I")
A18: CAL | B18: Líder de calidad (QA/QC) | C18: =COUNTIF('Matriz RACI'!$R$6:$R$65,"R") | D18: =COUNTIF('Matriz RACI'!$R$6:$R$65,"A") | E18: =COUNTIF('Matriz RACI'!$R$6:$R$65,"C") | F18: =COUNTIF('Matriz RACI'!$R$6:$R$65,"I")
A19: COM | B19: Líder de comisionamiento | C19: =COUNTIF('Matriz RACI'!$S$6:$S$65,"R") | D19: =COUNTIF('Matriz RACI'!$S$6:$S$65,"A") | E19: =COUNTIF('Matriz RACI'!$S$6:$S$65,"C") | F19: =COUNTIF('Matriz RACI'!$S$6:$S$65,"I")
A20: SUB | B20: Subcontratista de especialidad | C20: =COUNTIF('Matriz RACI'!$T$6:$T$65,"R") | D20: =COUNTIF('Matriz RACI'!$T$6:$T$65,"A") | E20: =COUNTIF('Matriz RACI'!$T$6:$T$65,"C") | F20: =COUNTIF('Matriz RACI'!$T$6:$T$65,"I")

Sheet Listas
A1: Valores de las listas desplegables. Puede ampliarlas agregando valores al final de cada columna y ajustando el rango con nombre (Fórmulas > Administrador de nombres).
A2: Etapas | B2: FasesExt | C2: Roles | D2: CodigosRol
A3: Planificación temprana (FEL) | B3: Fase 1 | C3: Gerente del proyecto del cliente | D3: CLI
A4: Ingeniería | B4: Fase 2 | C4: Gerente de Proyecto | D4: GP
A5: Procura | B5: Fase 3 | C5: AWP Champion | D5: CHA
A6: Construcción | B6: Fases 1 y 2 | C6: Líder de WFP | D6: LWF
A7: Comisionamiento | B7: Fases 2 y 3 | C7: Planificador de frente de trabajo | D7: WFP
B8: Todas las fases | C8: Líder de Ingeniería | D8: ING
C9: Líder de Procura | D9: PRO
C10: Gestor de materiales | D10: MAT
C11: Gerente de Construcción | D11: CON
C12: Superintendente / capataz general | D12: SUP
C13: Controles del proyecto | D13: CTR
C14: Coordinador de gestión de información | D14: IM
C15: Líder de HSE | D15: HSE
C16: Líder de calidad (QA/QC) | D16: CAL
C17: Líder de comisionamiento | D17: COM
C18: Subcontratista de especialidad | D18: SUB
